2025-07-09 12:25:26,434 - psichat - ERROR - error:93 - Excepción HTTP capturada | Error: 404: Not Found | Traceback: Traceback (most recent call last):
  File "C:\Users\Usuario\AppData\Local\Programs\Python\Python311\Lib\site-packages\starlette\_exception_handler.py", line 42, in wrapped_app
    await app(scope, receive, sender)
  File "C:\Users\Usuario\AppData\Local\Programs\Python\Python311\Lib\site-packages\starlette\routing.py", line 714, in __call__
    await self.middleware_stack(scope, receive, send)
  File "C:\Users\Usuario\AppData\Local\Programs\Python\Python311\Lib\site-packages\starlette\routing.py", line 764, in app
    await self.default(scope, receive, send)
  File "C:\Users\Usuario\AppData\Local\Programs\Python\Python311\Lib\site-packages\starlette\routing.py", line 650, in not_found
    raise HTTPException(status_code=404)
starlette.exceptions.HTTPException: 404: Not Found
 | Data: {"method": "GET", "url": "http://127.0.0.1:8000/favicon.ico", "status_code": 404}
2025-07-09 16:18:03,356 - psichat - ERROR - error:93 - Excepción HTTP capturada | Error: 401: No se pudo validar el token. | Traceback: Traceback (most recent call last):
  File "C:\Users\Usuario\AppData\Local\Programs\Python\Python311\Lib\site-packages\starlette\_exception_handler.py", line 42, in wrapped_app
    await app(scope, receive, sender)
  File "C:\Users\Usuario\AppData\Local\Programs\Python\Python311\Lib\site-packages\starlette\routing.py", line 73, in app
    response = await f(request)
               ^^^^^^^^^^^^^^^^
  File "C:\Users\Usuario\AppData\Local\Programs\Python\Python311\Lib\contextlib.py", line 222, in __aexit__
    await self.gen.athrow(typ, value, traceback)
  File "C:\Users\Usuario\AppData\Local\Programs\Python\Python311\Lib\site-packages\fastapi\concurrency.py", line 35, in contextmanager_in_threadpool
    raise e
  File "C:\Users\Usuario\AppData\Local\Programs\Python\Python311\Lib\site-packages\fastapi\concurrency.py", line 27, in contextmanager_in_threadpool
    yield await run_in_threadpool(cm.__enter__)
  File "C:\Users\Usuario\AppData\Local\Programs\Python\Python311\Lib\site-packages\fastapi\routing.py", line 291, in app
    solved_result = await solve_dependencies(
                    ^^^^^^^^^^^^^^^^^^^^^^^^^
  File "C:\Users\Usuario\AppData\Local\Programs\Python\Python311\Lib\site-packages\fastapi\dependencies\utils.py", line 640, in solve_dependencies
    solved = await run_in_threadpool(call, **solved_result.values)
             ^^^^^^^^^^^^^^^^^^^^^^^^^^^^^^^^^^^^^^^^^^^^^^^^^^^^^
  File "C:\Users\Usuario\AppData\Local\Programs\Python\Python311\Lib\site-packages\starlette\concurrency.py", line 37, in run_in_threadpool
    return await anyio.to_thread.run_sync(func)
           ^^^^^^^^^^^^^^^^^^^^^^^^^^^^^^^^^^^^
  File "C:\Users\Usuario\AppData\Local\Programs\Python\Python311\Lib\site-packages\anyio\to_thread.py", line 56, in run_sync
    return await get_async_backend().run_sync_in_worker_thread(
           ^^^^^^^^^^^^^^^^^^^^^^^^^^^^^^^^^^^^^^^^^^^^^^^^^^^^
  File "C:\Users\Usuario\AppData\Local\Programs\Python\Python311\Lib\site-packages\anyio\_backends\_asyncio.py", line 2470, in run_sync_in_worker_thread
    return await future
           ^^^^^^^^^^^^
  File "C:\Users\Usuario\AppData\Local\Programs\Python\Python311\Lib\site-packages\anyio\_backends\_asyncio.py", line 967, in run
    result = context.run(func, *args)
             ^^^^^^^^^^^^^^^^^^^^^^^^
  File "C:\Users\Usuario\Desktop\PsiChat\backend\app\api\routes\auth.py", line 74, in get_current_user
    raise credentials_exception
fastapi.exceptions.HTTPException: 401: No se pudo validar el token.
 | Data: {"method": "GET", "url": "http://127.0.0.1:8000/auth/me", "status_code": 401}
2025-07-09 16:18:03,405 - psichat - ERROR - error:93 - Excepción HTTP capturada | Error: 401: No se pudo validar el token. | Traceback: Traceback (most recent call last):
  File "C:\Users\Usuario\AppData\Local\Programs\Python\Python311\Lib\site-packages\starlette\_exception_handler.py", line 42, in wrapped_app
    await app(scope, receive, sender)
  File "C:\Users\Usuario\AppData\Local\Programs\Python\Python311\Lib\site-packages\starlette\routing.py", line 73, in app
    response = await f(request)
               ^^^^^^^^^^^^^^^^
  File "C:\Users\Usuario\AppData\Local\Programs\Python\Python311\Lib\contextlib.py", line 222, in __aexit__
    await self.gen.athrow(typ, value, traceback)
  File "C:\Users\Usuario\AppData\Local\Programs\Python\Python311\Lib\site-packages\fastapi\concurrency.py", line 35, in contextmanager_in_threadpool
    raise e
  File "C:\Users\Usuario\AppData\Local\Programs\Python\Python311\Lib\site-packages\fastapi\concurrency.py", line 27, in contextmanager_in_threadpool
    yield await run_in_threadpool(cm.__enter__)
  File "C:\Users\Usuario\AppData\Local\Programs\Python\Python311\Lib\site-packages\fastapi\routing.py", line 291, in app
    solved_result = await solve_dependencies(
                    ^^^^^^^^^^^^^^^^^^^^^^^^^
  File "C:\Users\Usuario\AppData\Local\Programs\Python\Python311\Lib\site-packages\fastapi\dependencies\utils.py", line 640, in solve_dependencies
    solved = await run_in_threadpool(call, **solved_result.values)
             ^^^^^^^^^^^^^^^^^^^^^^^^^^^^^^^^^^^^^^^^^^^^^^^^^^^^^
  File "C:\Users\Usuario\AppData\Local\Programs\Python\Python311\Lib\site-packages\starlette\concurrency.py", line 37, in run_in_threadpool
    return await anyio.to_thread.run_sync(func)
           ^^^^^^^^^^^^^^^^^^^^^^^^^^^^^^^^^^^^
  File "C:\Users\Usuario\AppData\Local\Programs\Python\Python311\Lib\site-packages\anyio\to_thread.py", line 56, in run_sync
    return await get_async_backend().run_sync_in_worker_thread(
           ^^^^^^^^^^^^^^^^^^^^^^^^^^^^^^^^^^^^^^^^^^^^^^^^^^^^
  File "C:\Users\Usuario\AppData\Local\Programs\Python\Python311\Lib\site-packages\anyio\_backends\_asyncio.py", line 2470, in run_sync_in_worker_thread
    return await future
           ^^^^^^^^^^^^
  File "C:\Users\Usuario\AppData\Local\Programs\Python\Python311\Lib\site-packages\anyio\_backends\_asyncio.py", line 967, in run
    result = context.run(func, *args)
             ^^^^^^^^^^^^^^^^^^^^^^^^
  File "C:\Users\Usuario\Desktop\PsiChat\backend\app\api\routes\auth.py", line 74, in get_current_user
    raise credentials_exception
fastapi.exceptions.HTTPException: 401: No se pudo validar el token.
 | Data: {"method": "GET", "url": "http://127.0.0.1:8000/auth/me", "status_code": 401}
2025-07-09 16:18:14,618 - psichat - ERROR - error:93 - Excepción HTTP capturada | Error: 404: Not Found | Traceback: Traceback (most recent call last):
  File "C:\Users\Usuario\AppData\Local\Programs\Python\Python311\Lib\site-packages\starlette\_exception_handler.py", line 42, in wrapped_app
    await app(scope, receive, sender)
  File "C:\Users\Usuario\AppData\Local\Programs\Python\Python311\Lib\site-packages\starlette\routing.py", line 714, in __call__
    await self.middleware_stack(scope, receive, send)
  File "C:\Users\Usuario\AppData\Local\Programs\Python\Python311\Lib\site-packages\starlette\routing.py", line 764, in app
    await self.default(scope, receive, send)
  File "C:\Users\Usuario\AppData\Local\Programs\Python\Python311\Lib\site-packages\starlette\routing.py", line 650, in not_found
    raise HTTPException(status_code=404)
starlette.exceptions.HTTPException: 404: Not Found
 | Data: {"method": "GET", "url": "http://127.0.0.1:8000/favicon.ico", "status_code": 404}
2025-07-09 16:18:31,124 - psichat - ERROR - error:93 - Error de validación capturado | Error: [{'type': 'missing', 'loc': ('body', 'username'), 'msg': 'Field required', 'input': None}, {'type': 'missing', 'loc': ('body', 'password'), 'msg': 'Field required', 'input': None}] | Traceback: Traceback (most recent call last):
  File "C:\Users\Usuario\AppData\Local\Programs\Python\Python311\Lib\site-packages\starlette\_exception_handler.py", line 42, in wrapped_app
    await app(scope, receive, sender)
  File "C:\Users\Usuario\AppData\Local\Programs\Python\Python311\Lib\site-packages\starlette\routing.py", line 73, in app
    response = await f(request)
               ^^^^^^^^^^^^^^^^
  File "C:\Users\Usuario\AppData\Local\Programs\Python\Python311\Lib\site-packages\fastapi\routing.py", line 346, in app
    raise validation_error
fastapi.exceptions.RequestValidationError: [{'type': 'missing', 'loc': ('body', 'username'), 'msg': 'Field required', 'input': None}, {'type': 'missing', 'loc': ('body', 'password'), 'msg': 'Field required', 'input': None}]
 | Data: {"method": "POST", "url": "http://127.0.0.1:8000/auth/login", "errors": [{"type": "missing", "loc": ["body", "username"], "msg": "Field required", "input": null}, {"type": "missing", "loc": ["body", "password"], "msg": "Field required", "input": null}]}
2025-07-09 16:18:31,577 - psichat - ERROR - error:93 - Request falló | Error: Object of type FormData is not JSON serializable | Traceback: Traceback (most recent call last):
  File "C:\Users\Usuario\AppData\Local\Programs\Python\Python311\Lib\site-packages\starlette\middleware\base.py", line 148, in call_next
    message = await recv_stream.receive()
              ^^^^^^^^^^^^^^^^^^^^^^^^^^^
  File "C:\Users\Usuario\AppData\Local\Programs\Python\Python311\Lib\site-packages\anyio\streams\memory.py", line 126, in receive
    raise EndOfStream from None
anyio.EndOfStream

During handling of the above exception, another exception occurred:

Traceback (most recent call last):
  File "C:\Users\Usuario\Desktop\PsiChat\backend\app\main.py", line 95, in log_requests
    response = await call_next(request)
               ^^^^^^^^^^^^^^^^^^^^^^^^
  File "C:\Users\Usuario\AppData\Local\Programs\Python\Python311\Lib\site-packages\starlette\middleware\base.py", line 156, in call_next
    raise app_exc
  File "C:\Users\Usuario\AppData\Local\Programs\Python\Python311\Lib\site-packages\starlette\middleware\base.py", line 141, in coro
    await self.app(scope, receive_or_disconnect, send_no_error)
  File "C:\Users\Usuario\AppData\Local\Programs\Python\Python311\Lib\site-packages\starlette\middleware\cors.py", line 93, in __call__
    await self.simple_response(scope, receive, send, request_headers=headers)
  File "C:\Users\Usuario\AppData\Local\Programs\Python\Python311\Lib\site-packages\starlette\middleware\cors.py", line 144, in simple_response
    await self.app(scope, receive, send)
  File "C:\Users\Usuario\AppData\Local\Programs\Python\Python311\Lib\site-packages\starlette\middleware\exceptions.py", line 62, in __call__
    await wrap_app_handling_exceptions(self.app, conn)(scope, receive, send)
  File "C:\Users\Usuario\AppData\Local\Programs\Python\Python311\Lib\site-packages\starlette\_exception_handler.py", line 53, in wrapped_app
    raise exc
  File "C:\Users\Usuario\AppData\Local\Programs\Python\Python311\Lib\site-packages\starlette\_exception_handler.py", line 42, in wrapped_app
    await app(scope, receive, sender)
  File "C:\Users\Usuario\AppData\Local\Programs\Python\Python311\Lib\site-packages\starlette\routing.py", line 714, in __call__
    await self.middleware_stack(scope, receive, send)
  File "C:\Users\Usuario\AppData\Local\Programs\Python\Python311\Lib\site-packages\starlette\routing.py", line 734, in app
    await route.handle(scope, receive, send)
  File "C:\Users\Usuario\AppData\Local\Programs\Python\Python311\Lib\site-packages\starlette\routing.py", line 288, in handle
    await self.app(scope, receive, send)
  File "C:\Users\Usuario\AppData\Local\Programs\Python\Python311\Lib\site-packages\starlette\routing.py", line 76, in app
    await wrap_app_handling_exceptions(app, request)(scope, receive, send)
  File "C:\Users\Usuario\AppData\Local\Programs\Python\Python311\Lib\site-packages\starlette\_exception_handler.py", line 59, in wrapped_app
    response = await handler(conn, exc)
               ^^^^^^^^^^^^^^^^^^^^^^^^
  File "C:\Users\Usuario\Desktop\PsiChat\backend\app\main.py", line 177, in validation_exception_handler
    return JSONResponse(
           ^^^^^^^^^^^^^
  File "C:\Users\Usuario\AppData\Local\Programs\Python\Python311\Lib\site-packages\starlette\responses.py", line 182, in __init__
    super().__init__(content, status_code, headers, media_type, background)
  File "C:\Users\Usuario\AppData\Local\Programs\Python\Python311\Lib\site-packages\starlette\responses.py", line 45, in __init__
    self.body = self.render(content)
                ^^^^^^^^^^^^^^^^^^^^
  File "C:\Users\Usuario\AppData\Local\Programs\Python\Python311\Lib\site-packages\starlette\responses.py", line 185, in render
    return json.dumps(
           ^^^^^^^^^^^
  File "C:\Users\Usuario\AppData\Local\Programs\Python\Python311\Lib\json\__init__.py", line 238, in dumps
    **kw).encode(obj)
          ^^^^^^^^^^^
  File "C:\Users\Usuario\AppData\Local\Programs\Python\Python311\Lib\json\encoder.py", line 200, in encode
    chunks = self.iterencode(o, _one_shot=True)
             ^^^^^^^^^^^^^^^^^^^^^^^^^^^^^^^^^^
  File "C:\Users\Usuario\AppData\Local\Programs\Python\Python311\Lib\json\encoder.py", line 258, in iterencode
    return _iterencode(o, 0)
           ^^^^^^^^^^^^^^^^^
  File "C:\Users\Usuario\AppData\Local\Programs\Python\Python311\Lib\json\encoder.py", line 180, in default
    raise TypeError(f'Object of type {o.__class__.__name__} '
TypeError: Object of type FormData is not JSON serializable
 | Data: {"method": "POST", "url": "http://127.0.0.1:8000/auth/login", "duration_ms": 93.87}
